// what is the output? and explain why?

// 1
Promise.resolve(1)
  .then(res => {
    console.log(res);
    return 2;
  })
  .catch(err => {
    return 3;
  })
  .then(res => {
    console.log(res);
  });

  //1 2
// promise resolved with value 1, first then print 1, return 2 to second then, second then print 2

// // 2
Promise.reject(1)
  .then(res => {
    console.log(res);
    return 2;
  })
  .catch(err => {
    console.log(err);
    return 3;
  })
  .then(res => {
    console.log(res);
  });
//1 3
//promise rejected with value 1, executes catch, catch print 1, return 3 to second then, second then print 3


//3
function runAsync(x) {
  const p = new Promise(resolve =>
    setTimeout(() => resolve(x), 1000)
  );
  return p;
}

function runReject(x) {
  const p = new Promise((resolve, reject) =>
    setTimeout(() => reject(`Error: ${x}`), 1000 * x)
  );
  return p;
}

Promise.all([runAsync(1), runReject(4), runAsync(3), runReject(2)])
  .then(res => console.log(res))
  .catch(err => console.log(err));

// Error: 2
// Promise.all resolves only if all promises resolve successfully, if any of the promises rejects, it immediately rejects with the reason of the first rejected promise.
// runReject 2 rejects first, catch get 2 from it. 
